<?xml version="1.0" ?>
<robot name="turtlebot3_burger" xmlns:xacro="http://ros.org/wiki/xacro">
  <xacro:include filename="$(find turtlebot3_description)/urdf/common_properties.xacro"/>
  <xacro:include filename="$(find turtlebot3_description)/urdf/turtlebot3_burger.gazebo.xacro"/>

  <link name="base_footprint"/>

  <joint name="base_joint" type="fixed">
    <parent link="base_footprint"/>
    <child link="base_link"/>
    <origin xyz="0.0 0.0 0.010" rpy="0 0 0"/>
  </joint>

 <link name="base_link">
    <!-- pose and inertial -->
    <inertial>
      <mass value="10"/>
      <origin xyz="0 0 0" rpy="0 0 0"/>
      <inertia ixx="1.66667" ixy="0" ixz="0" iyy="1.66667" iyz="0" izz="1.66667"/>
    </inertial>
    <collision name="base_collision">
      <origin xyz="0.0 0.0  0.05" rpy="0 0 0"/>
      <geometry>
        <box size="0.56 0.418 0.23"/>
      </geometry>
    </collision>
    <visual name="base_visual">
      <origin xyz="0.0 0.0  0.05" rpy="0 0 0"/>
      <geometry>
        <box size="0.56 0.418 0.23"/>
      </geometry>
      <material name="orange"/>
    </visual>

    <!-- caster front -->
    <collision name="caster_front_collision">
      <origin xyz="0.2 0 -0.07" rpy="0 0 0"/>
      <geometry>
        <sphere radius="0.02"/>
      </geometry>
      <surface>
        <friction>
          <ode>
            <mu>0</mu>
            <mu2>0</mu2>
            <slip1>1.0</slip1>
            <slip2>1.0</slip2>
          </ode>
        </friction>
      </surface>
    </collision>
    <visual name="caster_front_visual">
      <origin xyz="0.2 0 -0.07" rpy="0 0 0"/>
      <geometry>
        <sphere radius="0.02"/>
      </geometry>
       </visual>
      <!-- caster behind -->
       <collision name="caster_front_collision">
      <origin xyz="-0.2 0 -0.07" rpy="0 0 0"/>
      <geometry>
        <sphere radius="0.02"/>
      </geometry>
      <surface>
        <friction>
          <ode>
            <mu>0</mu>
            <mu2>0</mu2>
            <slip1>1.0</slip1>
            <slip2>1.0</slip2>
          </ode>
        </friction>
      </surface>
    </collision>
    <visual name="caster_front_visual">
      <origin xyz="-0.2 0 -0.07" rpy="0 0 0"/>
      <geometry>
        <sphere radius="0.02"/>
      </geometry>
       </visual>
  </link>

  <!-- right wheel -->
  <link name="wheel_right_link">
    <inertial>
      <mass value="1"/>
      <origin xyz="0 0 0" rpy="0 0 0"/>
      <inertia ixx="0.145833" ixy="0" ixz="0" iyy="0.145833" iyz="0" izz="0.125"/>
    </inertial>
    <collision name="link_right_wheel_collision">
      <origin xyz="0 0 0" rpy="0 0 0"/>
      <geometry>
        <cylinder radius="0.05" length="0.03"/>
      </geometry>
    </collision>
    <visual name="link_right_wheel_visual">
      <origin xyz="0 0 0" rpy="0 0 0"/>
      <geometry>
        <cylinder radius="0.05" length="0.03"/>
      </geometry>
      <material name="grey"/>
    </visual>
  </link>
  
  <!-- joint_right_wheel -->
  <joint name="wheel_right_joint" type="continuous">
    <parent link="base_link"/>
    <child link="link_right_wheel"/>
    <origin xyz="0.0 -0.20918 -0.04001" rpy="-1.57265  0       0"/>
    <axis xyz="0 0 1"/>
    <limit lower="-1.79769e+308" upper="1.79769e+308" effort="-1.0" velocity="-1.0"/>
  </joint>
  
  <!-- left wheel -->
   <link name="wheel_left_link">
    <inertial>
      <mass value="1"/>
      <origin xyz="0 0 0" rpy="0 0 0"/>
      <inertia ixx="0.145833" ixy="0" ixz="0" iyy="0.145833" iyz="0" izz="0.125"/>
    </inertial>
    <collision name="wheel_left_collilink_left_wheel_collisionsion">
      <origin xyz="0 0 0" rpy="0 0 0"/>
      <geometry>
        <cylinder radius="0.05" length="0.03"/>
      </geometry>
    </collision>
    <visual name="link_left_wheel_visual">
      <origin xyz="0 0 0" rpy="0 0 0"/>
      <geometry>
        <cylinder radius="0.05" length="0.03"/>
      </geometry>
      <material name="grey"/>
    </visual>
  </link>
  
  <!-- joint_left_wheel -->
  <joint name="wheel_left_joint" type="continuous">
    <parent link="base_link"/>
    <child link="link_left_wheel"/>
    <origin xyz="-0.0  0.20918 -0.04001" rpy="-1.57265  0       0"/>
    <axis xyz="0  0 1"/>
    <limit lower="-1.79769e+308" upper="1.79769e+308" effort="-1.0" velocity="-1.0"/>
  </joint>

  <joint name="imu_joint" type="fixed">
    <parent link="base_link"/>
    <child link="imu_link"/>
    <origin xyz="-0.032 0 0.068" rpy="0 0 0"/>
  </joint>

  <link name="imu_link"/>

  <joint name="scan_joint" type="fixed">
    <parent link="base_link"/>
    <child link="base_scan"/>
    <origin xyz="-0.032 0 0.172" rpy="0 0 0"/>
  </joint>
<!-- ///fix -->
  <link name="base_scan">
    <visual>
      <origin xyz="0 0 0.0" rpy="0 0 0"/>
      <geometry>
        <mesh filename="package://turtlebot3_description/meshes/sensors/lds.stl" scale="0.001 0.001 0.001"/>
      </geometry>
      <material name="dark"/>
    </visual>

    <collision>
      <origin xyz="0.015 0 -0.0065" rpy="0 0 0"/>
      <geometry>
        <cylinder length="0.0315" radius="0.055"/>
      </geometry>
    </collision>

    <inertial>
      <mass value="0.114" />
      <origin xyz="0 0 0" />
      <inertia ixx="0.001" ixy="0.0" ixz="0.0"
               iyy="0.001" iyz="0.0"
               izz="0.001" />
    </inertial>
  </link>

</robot>
